# This file was copied from python 3.8 stdlib, for use in python 3.7
# It is licensed as python see https://github.com/python/cpython/blob/master/LICENSE
# Any changes made for 3.7 were done under that license.

import asyncio
import inspect
import sys
from unittest.case import TestCase as _TestCase, _Outcome


class TestCase(_TestCase):  # pragma: nocover not testing the non async pieces
    def run(self, result=None):
        orig_result = result
        if result is None:
            result = self.defaultTestResult()
            startTestRun = getattr(result, "startTestRun", None)
            if startTestRun is not None:
                startTestRun()
        result.startTest(self)
        testMethod = getattr(self, self._testMethodName)
        if getattr(self.__class__, "__unittest_skip__", False) or getattr(
            testMethod, "__unittest_skip__", False
        ):
            # If the class or method was skipped.
            try:
                skip_why = getattr(
                    self.__class__, "__unittest_skip_why__", ""
                ) or getattr(testMethod, "__unittest_skip_why__", "")
                self._addSkip(result, self, skip_why)
            finally:
                result.stopTest(self)
            return
        expecting_failure_method = getattr(
            testMethod, "__unittest_expecting_failure__", False
        )
        expecting_failure_class = getattr(self, "__unittest_expecting_failure__", False)
        expecting_failure = expecting_failure_class or expecting_failure_method
        outcome = _Outcome(result)
        try:
            self._outcome = outcome

            with outcome.testPartExecutor(self):
                self._callSetUp()
            if outcome.success:
                outcome.expecting_failure = expecting_failure
                with outcome.testPartExecutor(self, isTest=True):
                    self._callTestMethod(testMethod)
                outcome.expecting_failure = False
                with outcome.testPartExecutor(self):
                    self._callTearDown()

            self.doCleanups()
            for test, reason in outcome.skipped:
                self._addSkip(result, test, reason)
            self._feedErrorsToResult(result, outcome.errors)
            if outcome.success:
                if expecting_failure:
                    if outcome.expectedFailure:
                        self._addExpectedFailure(result, outcome.expectedFailure)
                    else:
                        self._addUnexpectedSuccess(result)
                else:
                    result.addSuccess(self)
            return result
        finally:
            result.stopTest(self)
            if orig_result is None:
                stopTestRun = getattr(result, "stopTestRun", None)
                if stopTestRun is not None:
                    stopTestRun()
            # explicitly break reference cycles:
            # outcome.errors -> frame -> outcome -> outcome.errors
            # outcome.expectedFailure -> frame -> outcome -> outcome.expectedFailure
            outcome.errors.clear()
            outcome.expectedFailure = None
            # clear the outcome, no more needed
            self._outcome = None

    def doCleanups(self):
        """Execute all cleanup functions. Normally called for you after
        tearDown."""
        outcome = self._outcome or _Outcome()
        while self._cleanups:
            function, args, kwargs = self._cleanups.pop()
            with outcome.testPartExecutor(self):
                self._callCleanup(function, *args, **kwargs)

        # return this for backwards compatibility
        # even though we no longer use it internally
        return outcome.success


if sys.version_info[:2] < (3, 8):

    def handle_base_exception(fut, exc):
        # Due to a bug in 3.7, that was fixed in 3.8, if any BaseException is raised
        # from from a test will make it hang (discussion https://fburl.com/5ul4eol2).
        # This workaround sets up a new Exception that tries to mimic the original
        # BaseException name / message.
        exc_class = type(type(exc).__name__, (Exception,), {})
        new_ex = exc_class(str(exc))
        new_ex.__cause__ = exc
        fut.set_exception(new_ex)


else:

    def handle_base_exception(fut, exc):
        fut.set_exception(exc)


class IsolatedAsyncioTestCase(TestCase):
    # Names intentionally have a long prefix
    # to reduce a chance of clashing with user-defined attributes
    # from inherited test case
    #
    # The class doesn't call loop.run_until_complete(self.setUp()) and family
    # but uses a different approach:
    # 1. create a long-running task that reads self.setUp()
    #    awaitable from queue along with a future
    # 2. await the awaitable object passing in and set the result
    #    into the future object
    # 3. Outer code puts the awaitable and the future object into a queue
    #    with waiting for the future
    # The trick is necessary because every run_until_complete() call
    # creates a new task with embedded ContextVar context.
    # To share contextvars between setUp(), test and tearDown() we need to execute
    # them inside the same task.

    # Note: the test case modifies event loop policy if the policy was not instantiated
    # yet.
    # asyncio.get_event_loop_policy() creates a default policy on demand but never
    # returns None
    # I believe this is not an issue in user level tests but python itself for testing
    # should reset a policy in every test module
    # by calling asyncio.set_event_loop_policy(None) in tearDownModule()

    def __init__(self, methodName="runTest"):
        super().__init__(methodName)
        self._asyncioTestLoop = None
        self._asyncioCallsQueue = None

    async def asyncSetUp(self):
        pass

    async def asyncTearDown(self):
        pass

    def addAsyncCleanup(self, func, *args, **kwargs):
        # A trivial trampoline to addCleanup()
        # the function exists because it has a different semantics
        # and signature:
        # addCleanup() accepts regular functions
        # but addAsyncCleanup() accepts coroutines
        #
        # We intentionally don't add inspect.iscoroutinefunction() check
        # for func argument because there is no way
        # to check for async function reliably:
        # 1. It can be "async def func()" iself
        # 2. Class can implement "async def __call__()" method
        # 3. Regular "def func()" that returns awaitable object
        self.addCleanup(*(func, *args), **kwargs)

    def _callSetUp(self):
        self.setUp()
        self._callAsync(self.asyncSetUp)

    def _callTestMethod(self, method):
        self._callMaybeAsync(method)

    def _callTearDown(self):
        self._callAsync(self.asyncTearDown)
        self.tearDown()

    def _callCleanup(self, function, *args, **kwargs):
        self._callMaybeAsync(function, *args, **kwargs)

    def _callAsync(self, func, *args, **kwargs):
        assert self._asyncioTestLoop is not None
        ret = func(*args, **kwargs)
        assert inspect.isawaitable(ret)
        fut = self._asyncioTestLoop.create_future()
        self._asyncioCallsQueue.put_nowait((fut, ret))
        return self._asyncioTestLoop.run_until_complete(fut)

    def _callMaybeAsync(self, func, *args, **kwargs):
        assert self._asyncioTestLoop is not None
        ret = func(*args, **kwargs)
        if inspect.isawaitable(ret):
            fut = self._asyncioTestLoop.create_future()
            self._asyncioCallsQueue.put_nowait((fut, ret))
            return self._asyncioTestLoop.run_until_complete(fut)
        else:
            return ret  # pragma: nocover

    async def _asyncioLoopRunner(self, fut):
        self._asyncioCallsQueue = queue = asyncio.Queue()
        fut.set_result(None)
        while True:
            query = await queue.get()
            queue.task_done()
            if query is None:
                return
            fut, awaitable = query
            try:
                ret = await awaitable
                if not fut.cancelled():
                    fut.set_result(ret)
            except asyncio.CancelledError:  # pragma: nocover
                raise
            except Exception as ex:
                if not fut.cancelled():
                    fut.set_exception(ex)
            except BaseException as ex:
                if not fut.cancelled():
                    handle_base_exception(fut, ex)

    def _setupAsyncioLoop(self):
        assert self._asyncioTestLoop is None
        loop = asyncio.new_event_loop()
        asyncio.set_event_loop(loop)
        loop.set_debug(True)
        self._asyncioTestLoop = loop
        fut = loop.create_future()
        self._asyncioCallsTask = loop.create_task(self._asyncioLoopRunner(fut))
        loop.run_until_complete(fut)

    def _tearDownAsyncioLoop(self):
        assert self._asyncioTestLoop is not None
        loop = self._asyncioTestLoop
        self._asyncioTestLoop = None
        self._asyncioCallsQueue.put_nowait(None)
        loop.run_until_complete(self._asyncioCallsQueue.join())

        try:
            # cancel all tasks
            to_cancel = asyncio.all_tasks(loop)
            if not to_cancel:
                return

            for task in to_cancel:
                task.cancel()

            loop.run_until_complete(
                asyncio.gather(*to_cancel, loop=loop, return_exceptions=True)
            )

            for task in to_cancel:
                if task.cancelled():
                    continue
                if task.exception() is not None:  # pragma: nocover
                    loop.call_exception_handler(
                        {
                            "message": "unhandled exception during test shutdown",
                            "exception": task.exception(),
                            "task": task,
                        }
                    )
            # shutdown asyncgens
            loop.run_until_complete(loop.shutdown_asyncgens())
        finally:
            asyncio.set_event_loop(None)
            loop.close()

    def run(self, result=None):
        self._setupAsyncioLoop()
        try:
            return super().run(result)
        finally:
            self._tearDownAsyncioLoop()
