# Copyright (c) Meta Platforms, Inc. and affiliates.
#
# Licensed under the Apache License, Version 2.0 (the "License");
# you may not use this file except in compliance with the License.
# You may obtain a copy of the License at
#
#     http://www.apache.org/licenses/LICENSE-2.0
#
# Unless required by applicable law or agreed to in writing, software
# distributed under the License is distributed on an "AS IS" BASIS,
# WITHOUT WARRANTIES OR CONDITIONS OF ANY KIND, either express or implied.
# See the License for the specific language governing permissions and
# limitations under the License.

# pyre-strict
"""
This TestCase attempts to track all tasks so that they are ensured to have
been awaited. Any time asyncio calls logger.error() it is considered a
test failure.
"""

from __future__ import annotations

import asyncio
import asyncio.base_tasks
import asyncio.coroutines
import asyncio.futures
import asyncio.log
import asyncio.tasks
import reprlib
import sys
from collections.abc import Callable, Coroutine, Generator
from contextvars import Context
from functools import wraps
from typing import Generic, TYPE_CHECKING, TypeVar

_T = TypeVar("_T")
atleastpy38: bool = sys.version_info[:2] >= (3, 8)

# We can get rid of this when we drop support for 3.8
if TYPE_CHECKING:  # pragma: nocover

    class _BaseTask(asyncio.Task[_T]):
        pass

else:

    class _BaseTask(Generic[_T], asyncio.Task):
        pass


class TestTask(_BaseTask[_T]):
    _managed: bool = False
    _coro_repr: str

    # pyre-ignore[2]: We don't case *args and **kws has no type they are passed through
    def __init__(self, coro: Coroutine[object, object, _T], *args, **kws) -> None:
        # pyre-fixme[16]: Module `coroutines` has no attribute `_format_coroutine`.
        self._coro_repr = asyncio.coroutines._format_coroutine(coro)
        super().__init__(coro, *args, **kws)

    @reprlib.recursive_repr()
    def __repr__(self) -> str:
        repr_info = asyncio.base_tasks._task_repr_info(self)
        coro = f"coro={self._coro_repr}"
        if atleastpy38:  # py3.8 added name=
            repr_info[2] = coro  # pragma: nocover
        else:
            repr_info[1] = coro  # pragma: nocover
        return f"<{self.__class__.__name__} {' '.join(repr_info)}>"

    def _mark_managed(self) -> None:
        self._managed = True

    def __await__(self) -> Generator[object, None, _T]:
        self._mark_managed()
        return super().__await__()

    def result(self) -> _T:
        if self.done():
            self._mark_managed()

        return super().result()

    def exception(self) -> BaseException | None:
        if self.done():
            self._mark_managed()
        return super().exception()

    # pyre-fixme[14]: `add_done_callback` overrides method defined in `Future`
    #  inconsistently.
    def add_done_callback(
        self, fn: Callable[[asyncio.Task], None], *, context: Context | None = None
    ) -> None:
        @wraps(fn)
        def mark_managed(fut: asyncio.Task) -> None:
            self._mark_managed()
            return fn(fut)

        super().add_done_callback(mark_managed, context=context)

    def was_managed(self) -> bool:
        if self._managed:
            return True
        # If the task is done() and the result is None, let it pass as managed
        # We use super here so we don't manage ourselves.
        return (
            self.done()
            and not self.cancelled()
            and not super().exception()
            and super().result() is None
        )

    def __del__(self) -> None:
        # So a pattern is to create_task, and not save the results.
        # we accept that as long as there was no result other than None
        # thrift-py3 uses this pattern to call rpc methods in ServiceInterfaces
        # where any result/execption is returned to the remote client.
        if not self.was_managed():
            context = {
                "task": self,
                "message": (
                    "Task was destroyed but never awaited!, "
                    f"WrappedCoro: {self._coro_repr}"
                ),
            }
            # pyre-fixme[16]: `TestTask` has no attribute `_source_traceback`.
            if self._source_traceback:
                context["source_traceback"] = self._source_traceback
            self._loop.call_exception_handler(context)
        super().__del__()
